<?xml version="1.0" ?>
<robot name="robot_base" xmlns:xacro="http://www.ros.org/wiki/xacro">

<xacro:include filename="$(find robot_base_description)/urdf/materials.xacro" />
<!-- <xacro:include filename="$(find robot_base_description)/urdf/robot_base.trans" />
<xacro:include filename="$(find robot_base_description)/urdf/robot_base.gazebo" /> -->
<link name="base_link">
  <inertial>
    <origin xyz="0.006010434850842306 4.004864233089688e-07 0.13434207950453161" rpy="0 0 0"/>
    <mass value="45.929921070675896"/>
    <inertia ixx="1.062437" iyy="1.749946" izz="2.531226" ixy="-0.000378" iyz="-0.000123" ixz="0.01419"/>
  </inertial>
  <visual>
    <origin xyz="0 0 0" rpy="0 0 0"/>
    <geometry>
      <mesh filename="file://$(find robot_base_description)/meshes/base_link.stl" scale="0.001 0.001 0.001"/>
    </geometry>
    <material name="silver"/>
  </visual>
  <collision>
    <origin xyz="0 0 0" rpy="0 0 0"/>
    <geometry>
      <mesh filename="file://$(find robot_base_description)/meshes/base_link.stl" scale="0.001 0.001 0.001"/>
    </geometry>
  </collision>
</link>

<link name="left_front_wheel_1">
  <inertial>
    <origin xyz="-9.543055706773274e-09 0.03137916494591725 1.4559213505627167e-07" rpy="0 0 0"/>
    <mass value="0.9491110270115712"/>
    <inertia ixx="0.001555" iyy="0.002702" izz="0.001555" ixy="-0.0" iyz="0.0" ixz="-0.0"/>
  </inertial>
  <visual>
    <origin xyz="-0.19 -0.1805 -0.08" rpy="0 0 0"/>
    <geometry>
      <mesh filename="file://$(find robot_base_description)/meshes/left_front_wheel_1.stl" scale="0.001 0.001 0.001"/>
    </geometry>
    <material name="silver"/>
  </visual>
  <collision>
    <origin xyz="-0.19 -0.1805 -0.08" rpy="0 0 0"/>
    <geometry>
      <mesh filename="file://$(find robot_base_description)/meshes/left_front_wheel_1.stl" scale="0.001 0.001 0.001"/>
    </geometry>
  </collision>
</link>

<link name="left_back_wheel_1">
  <inertial>
    <origin xyz="-9.543055595750971e-09 0.03137916494591733 1.4559213526443848e-07" rpy="0 0 0"/>
    <mass value="0.9491110270115715"/>
    <inertia ixx="0.001555" iyy="0.002702" izz="0.001555" ixy="-0.0" iyz="0.0" ixz="-0.0"/>
  </inertial>
  <visual>
    <origin xyz="0.19 -0.1805 -0.08" rpy="0 0 0"/>
    <geometry>
      <mesh filename="file://$(find robot_base_description)/meshes/left_back_wheel_1.stl" scale="0.001 0.001 0.001"/>
    </geometry>
    <material name="silver"/>
  </visual>
  <collision>
    <origin xyz="0.19 -0.1805 -0.08" rpy="0 0 0"/>
    <geometry>
      <mesh filename="file://$(find robot_base_description)/meshes/left_back_wheel_1.stl" scale="0.001 0.001 0.001"/>
    </geometry>
  </collision>
</link>

<link name="right_back_wheel_1">
  <inertial>
    <origin xyz="2.3498597973015123e-07 -0.03137920521938581 -2.0518912122180488e-07" rpy="0 0 0"/>
    <mass value="0.9491111934993678"/>
    <inertia ixx="0.001555" iyy="0.002702" izz="0.001555" ixy="0.0" iyz="-0.0" ixz="-0.0"/>
  </inertial>
  <visual>
    <origin xyz="0.19 0.1805 -0.08" rpy="0 0 0"/>
    <geometry>
      <mesh filename="file://$(find robot_base_description)/meshes/right_back_wheel_1.stl" scale="0.001 0.001 0.001"/>
    </geometry>
    <material name="silver"/>
  </visual>
  <collision>
    <origin xyz="0.19 0.1805 -0.08" rpy="0 0 0"/>
    <geometry>
      <mesh filename="file://$(find robot_base_description)/meshes/right_back_wheel_1.stl" scale="0.001 0.001 0.001"/>
    </geometry>
  </collision>
</link>

<link name="right_front_wheel_1">
  <inertial>
    <origin xyz="2.3498597989668468e-07 -0.03137920521938581 -2.0518912093037134e-07" rpy="0 0 0"/>
    <mass value="0.94911119349937"/>
    <inertia ixx="0.001555" iyy="0.002702" izz="0.001555" ixy="0.0" iyz="-0.0" ixz="-0.0"/>
  </inertial>
  <visual>
    <origin xyz="-0.19 0.1805 -0.08" rpy="0 0 0"/>
    <geometry>
      <mesh filename="file://$(find robot_base_description)/meshes/right_front_wheel_1.stl" scale="0.001 0.001 0.001"/>
    </geometry>
    <material name="silver"/>
  </visual>
  <collision>
    <origin xyz="-0.19 0.1805 -0.08" rpy="0 0 0"/>
    <geometry>
      <mesh filename="file://$(find robot_base_description)/meshes/right_front_wheel_1.stl" scale="0.001 0.001 0.001"/>
    </geometry>
  </collision>
</link>

<link name="zed_mini_1">
  <inertial>
    <origin xyz="0.006890809169695311 -0.0011814639225888749 0.013252607692305629" rpy="0 0 0"/>
    <mass value="0.44647457908999766"/>
    <inertia ixx="0.000586" iyy="4.3e-05" izz="0.000583" ixy="6e-06" iyz="-0.0" ixz="0.0"/>
  </inertial>
  <visual>
    <origin xyz="-0.2525 -0.0 -0.1085" rpy="0 0 0"/>
    <geometry>
      <mesh filename="file://$(find robot_base_description)/meshes/zed_mini_1.stl" scale="0.001 0.001 0.001"/>
    </geometry>
    <material name="silver"/>
  </visual>
  <collision>
    <origin xyz="-0.2525 -0.0 -0.1085" rpy="0 0 0"/>
    <geometry>
      <mesh filename="file://$(find robot_base_description)/meshes/zed_mini_1.stl" scale="0.001 0.001 0.001"/>
    </geometry>
  </collision>
</link>

<link name="logo_1">
  <inertial>
    <origin xyz="-0.0030148374702534397 -0.0009578344360897588 -0.0011300936134206602" rpy="0 0 0"/>
    <mass value="0.07125256946293511"/>
    <inertia ixx="4e-05" iyy="8e-06" izz="3.3e-05" ixy="0.0" iyz="0.0" ixz="0.0"/>
  </inertial>
  <visual>
    <origin xyz="-0.26 -0.0 -0.08975" rpy="0 0 0"/>
    <geometry>
      <mesh filename="file://$(find robot_base_description)/meshes/logo_1.stl" scale="0.001 0.001 0.001"/>
    </geometry>
    <material name="silver"/>
  </visual>
  <collision>
    <origin xyz="-0.26 -0.0 -0.08975" rpy="0 0 0"/>
    <geometry>
      <mesh filename="file://$(find robot_base_description)/meshes/logo_1.stl" scale="0.001 0.001 0.001"/>
    </geometry>
  </collision>
</link>

<link name="jetson_1">
  <inertial>
    <origin xyz="-0.001882812378843579 -0.0012117915536683699 0.009224709951320367" rpy="0 0 0"/>
    <mass value="0.3773808086312594"/>
    <inertia ixx="0.000236" iyy="0.000221" izz="0.000415" ixy="6e-06" iyz="4e-06" ixz="1.9e-05"/>
  </inertial>
  <visual>
    <origin xyz="0.230479 -0.0 -0.108" rpy="0 0 0"/>
    <geometry>
      <mesh filename="file://$(find robot_base_description)/meshes/jetson_1.stl" scale="0.001 0.001 0.001"/>
    </geometry>
    <material name="silver"/>
  </visual>
  <collision>
    <origin xyz="0.230479 -0.0 -0.108" rpy="0 0 0"/>
    <geometry>
      <mesh filename="file://$(find robot_base_description)/meshes/jetson_1.stl" scale="0.001 0.001 0.001"/>
    </geometry>
  </collision>
</link>

<link name="lidar_1">
  <inertial>
    <origin xyz="0.041705900429680434 -3.652874609497409e-17 0.03970114222279103" rpy="0 0 0"/>
    <mass value="1.1515616542314224"/>
    <inertia ixx="0.000489" iyy="0.000861" izz="0.000987" ixy="-0.0" iyz="-0.0" ixz="-0.000148"/>
  </inertial>
  <visual>
    <origin xyz="-0.0 -0.0 -0.141" rpy="0 0 0"/>
    <geometry>
      <mesh filename="file://$(find robot_base_description)/meshes/lidar_1.stl" scale="0.001 0.001 0.001"/>
    </geometry>
    <material name="silver"/>
  </visual>
  <collision>
    <origin xyz="-0.0 -0.0 -0.141" rpy="0 0 0"/>
    <geometry>
      <mesh filename="file://$(find robot_base_description)/meshes/lidar_1.stl" scale="0.001 0.001 0.001"/>
    </geometry>
  </collision>
</link>

<link name="imu_1">
  <inertial>
    <origin xyz="-0.00998812297806373 9.133494040341156e-05 0.000862164665477741" rpy="0 0 0"/>
    <mass value="0.004997129426507204"/>
    <inertia ixx="0.0" iyy="0.0" izz="0.0" ixy="0.0" iyz="-0.0" ixz="-0.0"/>
  </inertial>
  <visual>
    <origin xyz="0.164479 -0.0 -0.108" rpy="0 0 0"/>
    <geometry>
      <mesh filename="file://$(find robot_base_description)/meshes/imu_1.stl" scale="0.001 0.001 0.001"/>
    </geometry>
    <material name="silver"/>
  </visual>
  <collision>
    <origin xyz="0.164479 -0.0 -0.108" rpy="0 0 0"/>
    <geometry>
      <mesh filename="file://$(find robot_base_description)/meshes/imu_1.stl" scale="0.001 0.001 0.001"/>
    </geometry>
  </collision>
</link>

<joint name="left_front_joint" type="continuous">
  <origin xyz="0.19 0.1805 0.08" rpy="0 0 0"/>
  <parent link="base_link"/>
  <child link="left_front_wheel_1"/>
  <axis xyz="0.0 1.0 0.0"/>
</joint>

<joint name="left_back_joint" type="continuous">
  <origin xyz="-0.19 0.1805 0.08" rpy="0 0 0"/>
  <parent link="base_link"/>
  <child link="left_back_wheel_1"/>
  <axis xyz="0.0 1.0 0.0"/>
</joint>

<joint name="right_back_joint" type="continuous">
  <origin xyz="-0.19 -0.1805 0.08" rpy="0 0 0"/>
  <parent link="base_link"/>
  <child link="right_back_wheel_1"/>
  <axis xyz="0.0 -1.0 0.0"/>
</joint>

<joint name="right_front_joint" type="continuous">
  <origin xyz="0.19 -0.1805 0.08" rpy="0 0 0"/>
  <parent link="base_link"/>
  <child link="right_front_wheel_1"/>
  <axis xyz="0.0 -1.0 0.0"/>
</joint>

<joint name="zed_mini_joint" type="fixed">
  <origin xyz="0.2525 0.0 0.1085" rpy="0 0 0"/>
  <parent link="base_link"/>
  <child link="zed_mini_1"/>
</joint>

<joint name="logo_joint" type="fixed">
  <origin xyz="0.26 0.0 0.08975" rpy="0 0 0"/>
  <parent link="base_link"/>
  <child link="logo_1"/>
</joint>

<joint name="jetson_joint" type="fixed">
  <origin xyz="-0.230479 0.0 0.108" rpy="0 0 0"/>
  <parent link="base_link"/>
  <child link="jetson_1"/>
</joint>

<joint name="lidar_joint" type="fixed">
  <origin xyz="0.0 0.0 0.141" rpy="0 0 0"/>
  <parent link="base_link"/>
  <child link="lidar_1"/>
</joint>

<joint name="imu_joint" type="fixed">
  <origin xyz="-0.164479 0.0 0.108" rpy="0 0 0"/>
  <parent link="base_link"/>
  <child link="imu_1"/>
</joint>

</robot>
